Workbook

Sheet SMPS 재고
A1: .
B2: SMPS 재고 | C2: =TODAY() -> 46149
C3: 오전 9:00:00 최신화
B5: 모델명 | C5: 수량
B6: APV 시리즈
B7: APV-12-12 | C7: =vlookup(B7,'재고 백업'!$A:$B,2,0) -> -
B8: APV-12-24 | C8: =vlookup(B8,'재고 백업'!$A:$B,2,0) -> -
B10: CSP 시리즈
B11: CSP-3000-120 | C11: =vlookup(B11,'재고 백업'!$A:$B,2,0) -> 6
B12: CSP-3000-400 | C12: =vlookup(B12,'재고 백업'!$A:$B,2,0) -> 17
B14: DBU시리즈
B15: DBU-3200-48 | C15: =vlookup(B15,'재고 백업'!$A:$B,2,0) -> -
B17: DDR 시리즈
B18: DDR-15G-3.3 | C18: =vlookup(B18,'재고 백업'!$A:$B,2,0) -> -
B19: DDR-15G-5 | C19: =vlookup(B19,'재고 백업'!$A:$B,2,0) -> 104
B20: DDR-15G-12 | C20: =vlookup(B20,'재고 백업'!$A:$B,2,0) -> 391 | E20: ㅛㅕㅕㅑㅕㅛㅑㅛㅕㅑ
B21: DDR-15G-15 | C21: =vlookup(B21,'재고 백업'!$A:$B,2,0) -> 151
B22: DDR-15G-24 | C22: =vlookup(B22,'재고 백업'!$A:$B,2,0) -> 131 | E22: ㅛㅕㅑㅛㅕㅑㅛㅕㅑ
B23: DDR-15L-5 | C23: =vlookup(B23,'재고 백업'!$A:$B,2,0) -> -
B24: DDR-15L-12 | C24: =vlookup(B24,'재고 백업'!$A:$B,2,0) -> 114
B25: DDR-15L-24 | C25: =vlookup(B25,'재고 백업'!$A:$B,2,0) -> 160
B26: DDR-30G-5 | C26: =vlookup(B26,'재고 백업'!$A:$B,2,0) -> 54
B27: DDR-30G-12 | C27: =vlookup(B27,'재고 백업'!$A:$B,2,0) -> 82
B28: DDR-30G-24 | C28: =vlookup(B28,'재고 백업'!$A:$B,2,0) -> 87
B29: DDR-30L-5 | C29: =vlookup(B29,'재고 백업'!$A:$B,2,0) -> 84
B30: DDR-30L-12 | C30: =vlookup(B30,'재고 백업'!$A:$B,2,0) -> 97
B31: DDR-30L-24 | C31: =vlookup(B31,'재고 백업'!$A:$B,2,0) -> -
B32: DDR-60G-5 | C32: =vlookup(B32,'재고 백업'!$A:$B,2,0) -> 116
B33: DDR-60G-12 | C33: =vlookup(B33,'재고 백업'!$A:$B,2,0) -> 85
B34: DDR-60G-24 | C34: =vlookup(B34,'재고 백업'!$A:$B,2,0) -> 45
... B51: DDR-480C-24 | C51: =vlookup(B51,'재고 백업'!$A:$B,2,0) -> 25
B53: DPU 시리즈
B54: DPU-3200-24 | C54: =vlookup(B54,'재고 백업'!$A:$B,2,0) -> -
B55: DPU-3200-48 | C55: =vlookup(B55,'재고 백업'!$A:$B,2,0) -> -
B57: DUBW 시리즈
B58: DPBW06F-15 | C58: =vlookup(B58,'재고 백업'!$A:$B,2,0) -> -
B60: DUPN 시리즈
B61: DPUN02L-15 | C61: =vlookup(B61,'재고 백업'!$A:$B,2,0) -> 202
B63: DRA시리즈
B64: DRA-40-12 | C64: =vlookup(B64,'재고 백업'!$A:$B,2,0) -> -
...

Sheet 재고 백업
A1: 일별 재고 파일
A2: 모델명 | B2: 재고현황
A3: CSP-3000-120 | B3: 6
A4: DDR-120C-24 | B4: 43
A5: DDR-15L-12 | B5: 114
A6: DDR-30G-5 | B6: 54
A7: DDR-30L-12 | B7: 97
A8: DDR-240C-24 | B8: 59
A9: DDR-480C-24 | B9: 25
A10: DDR-60G-12 | B10: 85
A11: DPUN02L-15 | B11: 202
A12: DRDN20-24 | B12: 40
A13: DUPS20 | B13: 41
A14: EDR-120-24 | B14: 215
... A38: HDR-60-12 | B38: 50
A39: HDR-60-24 | B39: -
A40: HDR-60-5 | B40: 73
A41: HLG-40H-24 | B41: 32
A42: HLG-120H-15A | B42: 133
A43: HLG-185H-24 | B43: 15
A44: HLG-185H-36A | B44: 24
A45: HLG-150H-30 | B45: 57
A46: HLG-150H-36A | B46: 1
A47: HRP-75-24 | B47: 106
A48: HRP-100-15 | B48: 146
A49: HRP-300-12 | B49: 93
A50: HRP-300-24 | B50: 90
A51: HRP-450-24 | B51: 112
... A84: LRS-200-5 | B84: 23
A85: LRS-350-12 | B85: -
A86: LRS-350-24 | B86: 491
A87: LRS-350-48 | B87: 828
A88: LRS-350-5 | B88: 29
A89: LRS-450-48 | B89: 4
A90: LRS-35-12 | B90: 653
A91: LRS-35-15 | B91: 176
A92: LRS-35-24 | B92: 581
A93: LRS-35-5 | B93: 183
A94: LRS-450-12 | B94: -
A95: LRS-450-24 | B95: 98
...

Sheet SMPS 재고 현황
B2: SMPS 재고 | D2: 26.01.01
C3: 매일 | D3: 오전 9:00:00 최신화
B5: 모델 선택 | C5: DRA
B7: 모델 | C7: 수량 | D7: 상태 | H7: =IFERROR(__xludf.DUMMYFUNCTION("SORT(UNIQUE(FILTER(#REF!, LEN(#REF!))))"),"#REF!") -> #REF!
B8: =IFERROR(__xludf.DUMMYFUNCTION("IF( $C$5="""", ""시리즈를 선택하세요"", SORT( FILTER( {'재고 백업'!A2:A620, '재고 백업'!B2:B620, #REF!}, #REF!=$C$5 ), 2, FALSE ) )"),"#REF!") -> #REF!
